<mujoco model="humanoid">
  <compiler angle="degree" inertiafromgeom="true" coordinate="global"/>
  <include file="./common/materials.xml"/>
  <visual>
    <headlight ambient=".4 .4 .4" diffuse=".8 .8 .8" specular="0.1 0.1 0.1"/>
    <map znear=".01"/>
    <quality shadowsize="2048"/>
  </visual>
  <default>
    <joint damping="0.0" armature="0.01" stiffness="0.0" limited="true"/>
    <geom conaffinity="7" condim="1" contype="7" margin="0.001" material="self" rgba="0.8 0.6 .4 1"/>
    <default class="expert">
        <geom conaffinity="7" condim="1" contype="7" margin="0.001" material="self" rgba="0.5 0.0 0.0 1"/>
    </default>
  </default>
  <statistic extent="3" center="0 0 1"/>
  <option timestep="0.00222222222">
    <flag contact="disable"/>
  </option>
  <asset>
    <texture type="skybox" file="./common/sky1.png" gridsize="3 4" gridlayout=".U..LFRB.D.." width="8192" height="8192"/>
    <texture builtin="flat" height="1278" mark="cross" markrgb="1 1 1" name="texgeom" random="0.01" rgb1=".8 .6 .4" rgb2=".8 .6 .4" type="cube" width="127"/>
    <material name="geom" emission="0.2" texture="texgeom" texuniform="true"/>
  </asset>
  <worldbody>
    <light cutoff="100" diffuse="1 1 1" dir="-0 0 -1.3" directional="true" exponent="1" pos="0 0 1.3" specular=".1 .1 .1"/>
    <geom condim="3" friction="1. .1 .1" material="grid" name="floor" pos="0 0 0" rgba=".8 .9 .8 1" size="100 100 .2" type="plane"/>
    <body name="Hips" user="0.0000 0.0146 0.0054" pos="0.0000 0.0146 0.0054">
      <joint armature="0" damping="0" limited="false" name="Hips" pos="0.0000 0.0000 0.0000" stiffness="0" type="free"/>
      <geom pos="0.0000 0.0000 0.0000" size="0.0950" type="sphere"/>
      <body name="Spine" user="0.0000 0.0591 0.1523" pos="0.0000 0.0146 0.0054">
        <geom fromto="-0.0550 0.0369 0.1109 0.0550 0.0369 0.1109" size="0.0420" type="capsule"/>
        <joint axis="1.0000 0.0000 0.0000" name="Spine_x" pos="0.0000 0.0439 0.0658" range="-180.0000 180.0000" type="hinge"/>
        <joint axis="0.0000 1.0000 0.0000" name="Spine_y" pos="0.0000 0.0439 0.0658" range="-180.0000 180.0000" type="hinge"/>
        <joint axis="0.0000 0.0000 1.0000" name="Spine_z" pos="0.0000 0.0439 0.0658" range="-180.0000 180.0000" type="hinge"/>
        <body name="Spine1" user="0.0000 0.0668 0.2397" pos="0.0000 0.0591 0.1523">
          <geom fromto="-0.0600 0.0630 0.1960 0.0600 0.0630 0.1960" size="0.0420" type="capsule"/>
          <joint axis="1.0000 0.0000 0.0000" name="Spine1_x" pos="0.0000 0.0591 0.1523" range="-180.0000 180.0000" type="hinge"/>
          <joint axis="0.0000 1.0000 0.0000" name="Spine1_y" pos="0.0000 0.0591 0.1523" range="-180.0000 180.0000" type="hinge"/>
          <joint axis="0.0000 0.0000 1.0000" name="Spine1_z" pos="0.0000 0.0591 0.1523" range="-180.0000 180.0000" type="hinge"/>
          <body name="Spine2" user="0.0000 0.0668 0.3275" pos="0.0000 0.0668 0.2397">
            <geom fromto="-0.0575 0.0668 0.2896 0.0575 0.0668 0.2896" size="0.0460" type="capsule"/>
            <joint axis="1.0000 0.0000 0.0000" name="Spine2_x" pos="0.0000 0.0668 0.2397" range="-180.0000 180.0000" type="hinge"/>
            <joint axis="0.0000 1.0000 0.0000" name="Spine2_y" pos="0.0000 0.0668 0.2397" range="-180.0000 180.0000" type="hinge"/>
            <joint axis="0.0000 0.0000 1.0000" name="Spine2_z" pos="0.0000 0.0668 0.2397" range="-180.0000 180.0000" type="hinge"/>
            <body name="Spine3" user="0.0000 0.0240 0.5074" pos="0.0000 0.0668 0.3275">
              <geom fromto="-0.0550 0.0454 0.3914 0.0550 0.0454 0.3914" size="0.0470" type="capsule"/>
              <joint axis="1.0000 0.0000 0.0000" name="Spine3_x" pos="0.0000 0.0668 0.3275" range="-180.0000 180.0000" type="hinge"/>
              <joint axis="0.0000 1.0000 0.0000" name="Spine3_y" pos="0.0000 0.0668 0.3275" range="-180.0000 180.0000" type="hinge"/>
              <joint axis="0.0000 0.0000 1.0000" name="Spine3_z" pos="0.0000 0.0668 0.3275" range="-180.0000 180.0000" type="hinge"/>
              <body name="Neck" user="0.0000 0.0129 0.6768" pos="0.0000 0.0240 0.5074">
                <joint axis="1.0000 0.0000 0.0000" name="Neck_x" pos="0.0000 0.0339 0.5579" range="-180.0000 180.0000" type="hinge"/>
                <joint axis="0.0000 1.0000 0.0000" name="Neck_y" pos="0.0000 0.0339 0.5579" range="-180.0000 180.0000" type="hinge"/>
                <joint axis="0.0000 0.0000 1.0000" name="Neck_z" pos="0.0000 0.0339 0.5579" range="-180.0000 180.0000" type="hinge"/>
                <geom fromto="0.0000 0.0304 0.5336 0.0000 0.0164 0.6131" size="0.0300" type="capsule"/>
                <body name="Head" user="0.0000 0.0129 0.8188" pos="0.0000 0.0129 0.6768">
                  <geom pos="0.0000 0.0129 0.6628" size="0.0750" type="sphere"/>
                  <joint axis="1.0000 0.0000 0.0000" name="Head_x" pos="0.0000 0.0129 0.6768" range="-180.0000 180.0000" type="hinge"/>
                  <joint axis="0.0000 1.0000 0.0000" name="Head_y" pos="0.0000 0.0129 0.6768" range="-180.0000 180.0000" type="hinge"/>
                  <joint axis="0.0000 0.0000 1.0000" name="Head_z" pos="0.0000 0.0129 0.6768" range="-180.0000 180.0000" type="hinge"/>
                </body>
              </body>
              <body name="RightShoulder" user="-0.1708 0.0191 0.4821" pos="0.0000 0.0240 0.5074">
                <joint axis="1.0000 0.0000 0.0000" name="RightShoulder_x" pos="-0.0286 0.0191 0.4821" range="-180.0000 180.0000" type="hinge"/>
                <joint axis="0.0000 1.0000 0.0000" name="RightShoulder_y" pos="-0.0286 0.0191 0.4821" range="-180.0000 180.0000" type="hinge"/>
                <joint axis="0.0000 0.0000 1.0000" name="RightShoulder_z" pos="-0.0286 0.0191 0.4821" range="-180.0000 180.0000" type="hinge"/>
                <geom fromto="-0.0486 0.0191 0.4821 -0.1508 0.0191 0.4821" size="0.0400" type="capsule"/>
                <body name="RightArm" user="-0.4103 0.0191 0.4821" pos="-0.1708 0.0191 0.4821">
                  <joint axis="1.0000 0.0000 0.0000" name="RightArm_x" pos="-0.1708 0.0191 0.4821" range="-180.0000 180.0000" type="hinge"/>
                  <joint axis="0.0000 1.0000 0.0000" name="RightArm_y" pos="-0.1708 0.0191 0.4821" range="-180.0000 180.0000" type="hinge"/>
                  <joint axis="0.0000 0.0000 1.0000" name="RightArm_z" pos="-0.1708 0.0191 0.4821" range="-180.0000 180.0000" type="hinge"/>
                  <geom fromto="-0.1908 0.0191 0.4821 -0.3903 0.0191 0.4821" size="0.0340" type="capsule"/>
                  <body name="RightForeArm" user="-0.6643 0.0191 0.4821" pos="-0.4103 0.0191 0.4821">
                    <joint axis="0.0000 0.0000 1.0000" name="RightForeArm_z" pos="-0.4103 0.0191 0.4821" range="-180.0000 180.0000" type="hinge"/>
                    <geom fromto="-0.4303 0.0191 0.4821 -0.6443 0.0191 0.4821" size="0.0300" type="capsule"/>
                    <body name="RightHand" user="-0.7282 0.0191 0.4821" pos="-0.6643 0.0191 0.4821">
                      <geom pos="-0.6683 0.0191 0.4821" size="0.0400" type="sphere"/>
                      <joint axis="1.0000 0.0000 0.0000" name="RightHand_x" pos="-0.6643 0.0191 0.4821" range="-180.0000 180.0000" type="hinge"/>
                      <joint axis="0.0000 1.0000 0.0000" name="RightHand_y" pos="-0.6643 0.0191 0.4821" range="-180.0000 180.0000" type="hinge"/>
                      <joint axis="0.0000 0.0000 1.0000" name="RightHand_z" pos="-0.6643 0.0191 0.4821" range="-180.0000 180.0000" type="hinge"/>
                    </body>
                  </body>
                </body>
              </body>
              <body name="LeftShoulder" user="0.1708 0.0191 0.4821" pos="-0.0000 0.0240 0.5074">
                <joint axis="1.0000 0.0000 0.0000" name="LeftShoulder_x" pos="0.0286 0.0191 0.4821" range="-180.0000 180.0000" type="hinge"/>
                <joint axis="0.0000 1.0000 0.0000" name="LeftShoulder_y" pos="0.0286 0.0191 0.4821" range="-180.0000 180.0000" type="hinge"/>
                <joint axis="0.0000 0.0000 1.0000" name="LeftShoulder_z" pos="0.0286 0.0191 0.4821" range="-180.0000 180.0000" type="hinge"/>
                <geom fromto="0.0486 0.0191 0.4821 0.1508 0.0191 0.4821" size="0.0400" type="capsule"/>
                <body name="LeftArm" user="0.4103 0.0191 0.4821" pos="0.1708 0.0191 0.4821">
                  <joint axis="1.0000 0.0000 0.0000" name="LeftArm_x" pos="0.1708 0.0191 0.4821" range="-180.0000 180.0000" type="hinge"/>
                  <joint axis="0.0000 1.0000 0.0000" name="LeftArm_y" pos="0.1708 0.0191 0.4821" range="-180.0000 180.0000" type="hinge"/>
                  <joint axis="0.0000 0.0000 1.0000" name="LeftArm_z" pos="0.1708 0.0191 0.4821" range="-180.0000 180.0000" type="hinge"/>
                  <geom fromto="0.1908 0.0191 0.4821 0.3903 0.0191 0.4821" size="0.0340" type="capsule"/>
                  <body name="LeftForeArm" user="0.6643 0.0191 0.4821" pos="0.4103 0.0191 0.4821">
                    <joint axis="0.0000 0.0000 1.0000" name="LeftForeArm_z" pos="0.4103 0.0191 0.4821" range="-180.0000 180.0000" type="hinge"/>
                    <geom fromto="0.4303 0.0191 0.4821 0.6443 0.0191 0.4821" size="0.0300" type="capsule"/>
                    <body name="LeftHand" user="0.7282 0.0191 0.4821" pos="0.6643 0.0191 0.4821">
                      <geom pos="0.6683 0.0191 0.4821" size="0.0400" type="sphere"/>
                      <joint axis="1.0000 0.0000 0.0000" name="LeftHand_x" pos="0.6643 0.0191 0.4821" range="-180.0000 180.0000" type="hinge"/>
                      <joint axis="0.0000 1.0000 0.0000" name="LeftHand_y" pos="0.6643 0.0191 0.4821" range="-180.0000 180.0000" type="hinge"/>
                      <joint axis="0.0000 0.0000 1.0000" name="LeftHand_z" pos="0.6643 0.0191 0.4821" range="-180.0000 180.0000" type="hinge"/>
                    </body>
                  </body>
                </body>
              </body>
            </body>
          </body>
        </body>
      </body>
      <body name="RightUpLeg" user="-0.0849 0.0000 -0.4027" pos="0.0000 0.0146 0.0054">
        <joint axis="1.0000 0.0000 0.0000" name="RightUpLeg_x" pos="-0.0849 0.0000 -0.0248" range="-180.0000 180.0000" type="hinge"/>
        <joint axis="0.0000 1.0000 0.0000" name="RightUpLeg_y" pos="-0.0849 0.0000 -0.0248" range="-180.0000 180.0000" type="hinge"/>
        <joint axis="0.0000 0.0000 1.0000" name="RightUpLeg_z" pos="-0.0849 0.0000 -0.0248" range="-180.0000 180.0000" type="hinge"/>
        <geom fromto="-0.0849 0.0000 -0.0448 -0.0849 0.0000 -0.3827" size="0.0490" type="capsule"/>
        <body name="RightLeg" user="-0.0849 0.0000 -0.7988" pos="-0.0849 0.0000 -0.4027">
          <joint axis="1.0000 0.0000 0.0000" name="RightLeg_x" pos="-0.0849 0.0000 -0.4027" range="-180.0000 180.0000" type="hinge"/>
          <geom contype="1" conaffinity="1" fromto="-0.0849 0.0000 -0.4227 -0.0849 0.0000 -0.7788" size="0.0400" type="capsule"/>
          <body name="RightFoot" user="-0.0849 -0.1308 -0.8464" pos="-0.0849 0.0000 -0.7988">
            <geom contype="1" conaffinity="1" pos="-0.0849 -0.0000 -0.8306" size="0.0400" type="sphere"/>
            <joint axis="1.0000 0.0000 0.0000" name="RightFoot_x" pos="-0.0849 0.0000 -0.7988" range="-180.0000 180.0000" type="hinge"/>
            <joint axis="0.0000 1.0000 0.0000" name="RightFoot_y" pos="-0.0849 0.0000 -0.7988" range="-180.0000 180.0000" type="hinge"/>
            <joint axis="0.0000 0.0000 1.0000" name="RightFoot_z" pos="-0.0849 0.0000 -0.7988" range="-180.0000 180.0000" type="hinge"/>
          </body>
        </body>
      </body>
      <body name="LeftUpLeg" user="0.0849 0.0000 -0.4027" pos="-0.0000 0.0146 0.0054">
        <joint axis="1.0000 0.0000 0.0000" name="LeftUpLeg_x" pos="0.0849 0.0000 -0.0248" range="-180.0000 180.0000" type="hinge"/>
        <joint axis="0.0000 1.0000 0.0000" name="LeftUpLeg_y" pos="0.0849 0.0000 -0.0248" range="-180.0000 180.0000" type="hinge"/>
        <joint axis="0.0000 0.0000 1.0000" name="LeftUpLeg_z" pos="0.0849 0.0000 -0.0248" range="-180.0000 180.0000" type="hinge"/>
        <geom fromto="0.0849 0.0000 -0.0448 0.0849 0.0000 -0.3827" size="0.0490" type="capsule"/>
        <body name="LeftLeg" user="0.0849 0.0000 -0.7988" pos="0.0849 0.0000 -0.4027">
          <joint axis="1.0000 0.0000 0.0000" name="LeftLeg_x" pos="0.0849 0.0000 -0.4027" range="-180.0000 180.0000" type="hinge"/>
          <geom contype="2" conaffinity="2" fromto="0.0849 0.0000 -0.4227 0.0849 0.0000 -0.7788" size="0.0400" type="capsule"/>
          <body name="LeftFoot" user="0.0849 -0.1308 -0.8464" pos="0.0849 0.0000 -0.7988">
            <geom contype="2" conaffinity="2" pos="0.0849 -0.0000 -0.8306" size="0.0400" type="sphere"/>
            <joint axis="1.0000 0.0000 0.0000" name="LeftFoot_x" pos="0.0849 0.0000 -0.7988" range="-180.0000 180.0000" type="hinge"/>
            <joint axis="0.0000 1.0000 0.0000" name="LeftFoot_y" pos="0.0849 0.0000 -0.7988" range="-180.0000 180.0000" type="hinge"/>
            <joint axis="0.0000 0.0000 1.0000" name="LeftFoot_z" pos="0.0849 0.0000 -0.7988" range="-180.0000 180.0000" type="hinge"/>
          </body>
        </body>
      </body>
    </body>
    <body name="e_Hips" childclass="expert" user="0.0000 0.0146 0.0054" pos="0.0000 0.0146 0.0054">
      <joint armature="0" damping="0" limited="false" name="e_Hips" pos="0.0000 0.0000 0.0000" stiffness="0" type="free"/>
      <geom pos="0.0000 0.0000 0.0000" size="0.0950" type="sphere"/>
      <body name="e_Spine" user="0.0000 0.0591 0.1523" pos="0.0000 0.0146 0.0054">
        <geom fromto="-0.0550 0.0369 0.1109 0.0550 0.0369 0.1109" size="0.0420" type="capsule"/>
        <joint axis="1.0000 0.0000 0.0000" name="e_Spine_x" pos="0.0000 0.0439 0.0658" range="-180.0000 180.0000" type="hinge"/>
        <joint axis="0.0000 1.0000 0.0000" name="e_Spine_y" pos="0.0000 0.0439 0.0658" range="-180.0000 180.0000" type="hinge"/>
        <joint axis="0.0000 0.0000 1.0000" name="e_Spine_z" pos="0.0000 0.0439 0.0658" range="-180.0000 180.0000" type="hinge"/>
        <body name="e_Spine1" user="0.0000 0.0668 0.2397" pos="0.0000 0.0591 0.1523">
          <geom fromto="-0.0600 0.0630 0.1960 0.0600 0.0630 0.1960" size="0.0420" type="capsule"/>
          <joint axis="1.0000 0.0000 0.0000" name="e_Spine1_x" pos="0.0000 0.0591 0.1523" range="-180.0000 180.0000" type="hinge"/>
          <joint axis="0.0000 1.0000 0.0000" name="e_Spine1_y" pos="0.0000 0.0591 0.1523" range="-180.0000 180.0000" type="hinge"/>
          <joint axis="0.0000 0.0000 1.0000" name="e_Spine1_z" pos="0.0000 0.0591 0.1523" range="-180.0000 180.0000" type="hinge"/>
          <body name="e_Spine2" user="0.0000 0.0668 0.3275" pos="0.0000 0.0668 0.2397">
            <geom fromto="-0.0575 0.0668 0.2896 0.0575 0.0668 0.2896" size="0.0460" type="capsule"/>
            <joint axis="1.0000 0.0000 0.0000" name="e_Spine2_x" pos="0.0000 0.0668 0.2397" range="-180.0000 180.0000" type="hinge"/>
            <joint axis="0.0000 1.0000 0.0000" name="e_Spine2_y" pos="0.0000 0.0668 0.2397" range="-180.0000 180.0000" type="hinge"/>
            <joint axis="0.0000 0.0000 1.0000" name="e_Spine2_z" pos="0.0000 0.0668 0.2397" range="-180.0000 180.0000" type="hinge"/>
            <body name="e_Spine3" user="0.0000 0.0240 0.5074" pos="0.0000 0.0668 0.3275">
              <geom fromto="-0.0550 0.0454 0.3914 0.0550 0.0454 0.3914" size="0.0470" type="capsule"/>
              <joint axis="1.0000 0.0000 0.0000" name="e_Spine3_x" pos="0.0000 0.0668 0.3275" range="-180.0000 180.0000" type="hinge"/>
              <joint axis="0.0000 1.0000 0.0000" name="e_Spine3_y" pos="0.0000 0.0668 0.3275" range="-180.0000 180.0000" type="hinge"/>
              <joint axis="0.0000 0.0000 1.0000" name="e_Spine3_z" pos="0.0000 0.0668 0.3275" range="-180.0000 180.0000" type="hinge"/>
              <body name="e_Neck" user="0.0000 0.0129 0.6768" pos="0.0000 0.0240 0.5074">
                <joint axis="1.0000 0.0000 0.0000" name="e_Neck_x" pos="0.0000 0.0339 0.5579" range="-180.0000 180.0000" type="hinge"/>
                <joint axis="0.0000 1.0000 0.0000" name="e_Neck_y" pos="0.0000 0.0339 0.5579" range="-180.0000 180.0000" type="hinge"/>
                <joint axis="0.0000 0.0000 1.0000" name="e_Neck_z" pos="0.0000 0.0339 0.5579" range="-180.0000 180.0000" type="hinge"/>
                <geom fromto="0.0000 0.0304 0.5336 0.0000 0.0164 0.6131" size="0.0300" type="capsule"/>
                <body name="e_Head" user="0.0000 0.0129 0.8188" pos="0.0000 0.0129 0.6768">
                  <geom pos="0.0000 0.0129 0.6628" size="0.0750" type="sphere"/>
                  <joint axis="1.0000 0.0000 0.0000" name="e_Head_x" pos="0.0000 0.0129 0.6768" range="-180.0000 180.0000" type="hinge"/>
                  <joint axis="0.0000 1.0000 0.0000" name="e_Head_y" pos="0.0000 0.0129 0.6768" range="-180.0000 180.0000" type="hinge"/>
                  <joint axis="0.0000 0.0000 1.0000" name="e_Head_z" pos="0.0000 0.0129 0.6768" range="-180.0000 180.0000" type="hinge"/>
                </body>
              </body>
              <body name="e_RightShoulder" user="-0.1708 0.0191 0.4821" pos="0.0000 0.0240 0.5074">
                <joint axis="1.0000 0.0000 0.0000" name="e_RightShoulder_x" pos="-0.0286 0.0191 0.4821" range="-180.0000 180.0000" type="hinge"/>
                <joint axis="0.0000 1.0000 0.0000" name="e_RightShoulder_y" pos="-0.0286 0.0191 0.4821" range="-180.0000 180.0000" type="hinge"/>
                <joint axis="0.0000 0.0000 1.0000" name="e_RightShoulder_z" pos="-0.0286 0.0191 0.4821" range="-180.0000 180.0000" type="hinge"/>
                <geom fromto="-0.0486 0.0191 0.4821 -0.1508 0.0191 0.4821" size="0.0400" type="capsule"/>
                <body name="e_RightArm" user="-0.4103 0.0191 0.4821" pos="-0.1708 0.0191 0.4821">
                  <joint axis="1.0000 0.0000 0.0000" name="e_RightArm_x" pos="-0.1708 0.0191 0.4821" range="-180.0000 180.0000" type="hinge"/>
                  <joint axis="0.0000 1.0000 0.0000" name="e_RightArm_y" pos="-0.1708 0.0191 0.4821" range="-180.0000 180.0000" type="hinge"/>
                  <joint axis="0.0000 0.0000 1.0000" name="e_RightArm_z" pos="-0.1708 0.0191 0.4821" range="-180.0000 180.0000" type="hinge"/>
                  <geom fromto="-0.1908 0.0191 0.4821 -0.3903 0.0191 0.4821" size="0.0340" type="capsule"/>
                  <body name="e_RightForeArm" user="-0.6643 0.0191 0.4821" pos="-0.4103 0.0191 0.4821">
                    <joint axis="0.0000 0.0000 1.0000" name="e_RightForeArm_z" pos="-0.4103 0.0191 0.4821" range="-180.0000 180.0000" type="hinge"/>
                    <geom fromto="-0.4303 0.0191 0.4821 -0.6443 0.0191 0.4821" size="0.0300" type="capsule"/>
                    <body name="e_RightHand" user="-0.7282 0.0191 0.4821" pos="-0.6643 0.0191 0.4821">
                      <geom pos="-0.6683 0.0191 0.4821" size="0.0400" type="sphere"/>
                      <joint axis="1.0000 0.0000 0.0000" name="e_RightHand_x" pos="-0.6643 0.0191 0.4821" range="-180.0000 180.0000" type="hinge"/>
                      <joint axis="0.0000 1.0000 0.0000" name="e_RightHand_y" pos="-0.6643 0.0191 0.4821" range="-180.0000 180.0000" type="hinge"/>
                      <joint axis="0.0000 0.0000 1.0000" name="e_RightHand_z" pos="-0.6643 0.0191 0.4821" range="-180.0000 180.0000" type="hinge"/>
                    </body>
                  </body>
                </body>
              </body>
              <body name="e_LeftShoulder" user="0.1708 0.0191 0.4821" pos="-0.0000 0.0240 0.5074">
                <joint axis="1.0000 0.0000 0.0000" name="e_LeftShoulder_x" pos="0.0286 0.0191 0.4821" range="-180.0000 180.0000" type="hinge"/>
                <joint axis="0.0000 1.0000 0.0000" name="e_LeftShoulder_y" pos="0.0286 0.0191 0.4821" range="-180.0000 180.0000" type="hinge"/>
                <joint axis="0.0000 0.0000 1.0000" name="e_LeftShoulder_z" pos="0.0286 0.0191 0.4821" range="-180.0000 180.0000" type="hinge"/>
                <geom fromto="0.0486 0.0191 0.4821 0.1508 0.0191 0.4821" size="0.0400" type="capsule"/>
                <body name="e_LeftArm" user="0.4103 0.0191 0.4821" pos="0.1708 0.0191 0.4821">
                  <joint axis="1.0000 0.0000 0.0000" name="e_LeftArm_x" pos="0.1708 0.0191 0.4821" range="-180.0000 180.0000" type="hinge"/>
                  <joint axis="0.0000 1.0000 0.0000" name="e_LeftArm_y" pos="0.1708 0.0191 0.4821" range="-180.0000 180.0000" type="hinge"/>
                  <joint axis="0.0000 0.0000 1.0000" name="e_LeftArm_z" pos="0.1708 0.0191 0.4821" range="-180.0000 180.0000" type="hinge"/>
                  <geom fromto="0.1908 0.0191 0.4821 0.3903 0.0191 0.4821" size="0.0340" type="capsule"/>
                  <body name="e_LeftForeArm" user="0.6643 0.0191 0.4821" pos="0.4103 0.0191 0.4821">
                    <joint axis="0.0000 0.0000 1.0000" name="e_LeftForeArm_z" pos="0.4103 0.0191 0.4821" range="-180.0000 180.0000" type="hinge"/>
                    <geom fromto="0.4303 0.0191 0.4821 0.6443 0.0191 0.4821" size="0.0300" type="capsule"/>
                    <body name="e_LeftHand" user="0.7282 0.0191 0.4821" pos="0.6643 0.0191 0.4821">
                      <geom pos="0.6683 0.0191 0.4821" size="0.0400" type="sphere"/>
                      <joint axis="1.0000 0.0000 0.0000" name="e_LeftHand_x" pos="0.6643 0.0191 0.4821" range="-180.0000 180.0000" type="hinge"/>
                      <joint axis="0.0000 1.0000 0.0000" name="e_LeftHand_y" pos="0.6643 0.0191 0.4821" range="-180.0000 180.0000" type="hinge"/>
                      <joint axis="0.0000 0.0000 1.0000" name="e_LeftHand_z" pos="0.6643 0.0191 0.4821" range="-180.0000 180.0000" type="hinge"/>
                    </body>
                  </body>
                </body>
              </body>
            </body>
          </body>
        </body>
      </body>
      <body name="e_RightUpLeg" user="-0.0849 0.0000 -0.4027" pos="0.0000 0.0146 0.0054">
        <joint axis="1.0000 0.0000 0.0000" name="e_RightUpLeg_x" pos="-0.0849 0.0000 -0.0248" range="-180.0000 180.0000" type="hinge"/>
        <joint axis="0.0000 1.0000 0.0000" name="e_RightUpLeg_y" pos="-0.0849 0.0000 -0.0248" range="-180.0000 180.0000" type="hinge"/>
        <joint axis="0.0000 0.0000 1.0000" name="e_RightUpLeg_z" pos="-0.0849 0.0000 -0.0248" range="-180.0000 180.0000" type="hinge"/>
        <geom fromto="-0.0849 0.0000 -0.0448 -0.0849 0.0000 -0.3827" size="0.0490" type="capsule"/>
        <body name="e_RightLeg" user="-0.0849 0.0000 -0.7988" pos="-0.0849 0.0000 -0.4027">
          <joint axis="1.0000 0.0000 0.0000" name="e_RightLeg_x" pos="-0.0849 0.0000 -0.4027" range="-180.0000 180.0000" type="hinge"/>
          <geom contype="1" conaffinity="1" fromto="-0.0849 0.0000 -0.4227 -0.0849 0.0000 -0.7788" size="0.0400" type="capsule"/>
          <body name="e_RightFoot" user="-0.0849 -0.1308 -0.8464" pos="-0.0849 0.0000 -0.7988">
            <geom contype="1" conaffinity="1" pos="-0.0849 -0.0000 -0.8306" size="0.0400" type="sphere"/>
            <joint axis="1.0000 0.0000 0.0000" name="e_RightFoot_x" pos="-0.0849 0.0000 -0.7988" range="-180.0000 180.0000" type="hinge"/>
            <joint axis="0.0000 1.0000 0.0000" name="e_RightFoot_y" pos="-0.0849 0.0000 -0.7988" range="-180.0000 180.0000" type="hinge"/>
            <joint axis="0.0000 0.0000 1.0000" name="e_RightFoot_z" pos="-0.0849 0.0000 -0.7988" range="-180.0000 180.0000" type="hinge"/>
          </body>
        </body>
      </body>
      <body name="e_LeftUpLeg" user="0.0849 0.0000 -0.4027" pos="-0.0000 0.0146 0.0054">
        <joint axis="1.0000 0.0000 0.0000" name="e_LeftUpLeg_x" pos="0.0849 0.0000 -0.0248" range="-180.0000 180.0000" type="hinge"/>
        <joint axis="0.0000 1.0000 0.0000" name="e_LeftUpLeg_y" pos="0.0849 0.0000 -0.0248" range="-180.0000 180.0000" type="hinge"/>
        <joint axis="0.0000 0.0000 1.0000" name="e_LeftUpLeg_z" pos="0.0849 0.0000 -0.0248" range="-180.0000 180.0000" type="hinge"/>
        <geom fromto="0.0849 0.0000 -0.0448 0.0849 0.0000 -0.3827" size="0.0490" type="capsule"/>
        <body name="e_LeftLeg" user="0.0849 0.0000 -0.7988" pos="0.0849 0.0000 -0.4027">
          <joint axis="1.0000 0.0000 0.0000" name="e_LeftLeg_x" pos="0.0849 0.0000 -0.4027" range="-180.0000 180.0000" type="hinge"/>
          <geom contype="2" conaffinity="2" fromto="0.0849 0.0000 -0.4227 0.0849 0.0000 -0.7788" size="0.0400" type="capsule"/>
          <body name="e_LeftFoot" user="0.0849 -0.1308 -0.8464" pos="0.0849 0.0000 -0.7988">
            <geom contype="2" conaffinity="2" pos="0.0849 -0.0000 -0.8306" size="0.0400" type="sphere"/>
            <joint axis="1.0000 0.0000 0.0000" name="e_LeftFoot_x" pos="0.0849 0.0000 -0.7988" range="-180.0000 180.0000" type="hinge"/>
            <joint axis="0.0000 1.0000 0.0000" name="e_LeftFoot_y" pos="0.0849 0.0000 -0.7988" range="-180.0000 180.0000" type="hinge"/>
            <joint axis="0.0000 0.0000 1.0000" name="e_LeftFoot_z" pos="0.0849 0.0000 -0.7988" range="-180.0000 180.0000" type="hinge"/>
          </body>
        </body>
      </body>
    </body>
  </worldbody>
</mujoco>
